Workbook

Sheet ★상담대시보드
A1: ★ 현장 상담 대시보드
A2: 코드·종목·목표만 입력하면 → 상담 내용이 전부 자동 출력. 이 화면 보며 상담하세요.
A4: [ 입력 ]
A5: 이름 | B5: 신지오 | D5: 선천 | E5: 대사 | F5: 생활
A6: BioCode (예: 2-1-2) | B6: 2-1-2 | D6: =VALUE(LEFT(B6,1)) | E6: =VALUE(MID(B6,3,1)) | F6: =VALUE(RIGHT(B6,1))
A7: 종목·포지션 | B7: 야구 내야수
A8: 목표수준 | B8: 프로
A10: [ 진단 — 코드에서 자동 ]
A11: 캐릭터명 | B11: =VLOOKUP($B$6,27코드마스터!$A$5:$R$31,5,FALSE())
A12: 타고난몸 (선천) | B12: =VLOOKUP($B$6,27코드마스터!$A$5:$R$31,6,FALSE())
A13: 체질 | B13: =VLOOKUP($B$6,27코드마스터!$A$5:$R$31,7,FALSE())
A14: 정신기질 | B14: =VLOOKUP($B$6,27코드마스터!$A$5:$R$31,8,FALSE())
A15: 현재몸 (대사) | B15: =VLOOKUP($B$6,27코드마스터!$A$5:$R$31,9,FALSE())
A16: 흡수 | B16: =VLOOKUP($B$6,27코드마스터!$A$5:$R$31,10,FALSE())
A17: 습관 (생활) | B17: =VLOOKUP($B$6,27코드마스터!$A$5:$R$31,14,FALSE())
A18: 수면 | B18: =VLOOKUP($B$6,27코드마스터!$A$5:$R$31,15,FALSE())
A19: 강점 | B19: =VLOOKUP($B$6,27코드마스터!$A$5:$R$31,17,FALSE())
A20: 취약점 | B20: =VLOOKUP($B$6,27코드마스터!$A$5:$R$31,18,FALSE())
A22: [ 바꿀 것 — 처방 ]
A23: 식단 | B23: =VLOOKUP($B$6,27코드마스터!$A$5:$R$31,11,FALSE())
A24: 식사방법 | B24: =VLOOKUP($B$6,27코드마스터!$A$5:$R$31,12,FALSE())
A25: 간식 | B25: =VLOOKUP($B$6,27코드마스터!$A$5:$R$31,13,FALSE())
A26: 운동방법 | B26: =VLOOKUP($B$6,27코드마스터!$A$5:$R$31,16,FALSE())
A28: [ 목표 비교 — 격려/경고 ]
A29: 목표 요구코드 | B29: =IFERROR(VLOOKUP($B$7,종목요구코드!$A$5:$E$12,5,FALSE()),"종목 미등록")
A30: 요구 선천/대사/생활 | B30: =IFERROR(VLOOKUP($B$7,종목요구코드!$A$5:$E$12,2,FALSE())&" / "&VLOOKUP($B$7,종목요구코드!$A$5:$E$12,3,FALSE())&" / "&VLOOKUP($B$7,종목요구코드!$A$5:$E$12,4,FALSE()),"-")
A31: 거리 (요구-현재 합) | B31: =IFERROR((VLOOKUP($B$7,종목요구코드!$A$5:$E$12,2,FALSE())-D6)+(VLOOKUP($B$7,종목요구코드!$A$5:$E$12,3,FALSE())-E6)+(VLOOKUP($B$7,종목요구코드!$A$5:$E$12,4,FALSE())-F6),"-")
A32: ★ 상담 메시지 | B32: =IF(OR($B$8="프로",$B$8="국대",$B$8="대학"),IF(B31>=2,"⚠ 목표가 높은데 채울 것이 많습니다. 지금 생활로는 부족 — 1년 집중 관리 필요",IF(B31>=1,"목표까지 한 걸음. 약한 축만 채우면 도달 가능","✓ 목표 대비 충분 — 잘하고 있습니다")),"취미·일반 목표 — 지금도 충분합니다. 부담 갖지 마세요")

Sheet ★컨트롤패널
A1: BioCode 333 엔진 v13 — 컨트롤 패널
A2: ★ 파란 셀만 수정하세요. 모든 수식이 이 값을 참조합니다 (하드코딩 없음).
A4: [ 3축 적용 비율 ]
A5: 축 | B5: 비율(%) | C5: 영역 | D5: 설명
A6: 1번 선천(유전) | B6: 60 | C6: 유전(고정) | D6: 타고난 골격·체질·기질
A7: 2번 대사 | B7: 22 | C7: 후천(가변) | D7: 흡수·저장 효율
A8: 3번 생활 | B8: 18 | C8: 후천(가변) | D8: 수면·활동·노력
A9: 합계(=100 검증) | B9: =SUM(B6:B8)
A10: 유전:후천 | B10: =B6&" : "&(B7+B8)
A12: [ 기타 계수 ]
A13: 파라미터 | B13: 값 | C13: 단위 | D13: 근거
A14: 종목 보정계수 | B14: 1.15 | C14: 배 | D14: 자체모델
A15: 환경여력(후천변동폭) | B15: 5 | C15: ±cm | D15: 성장도표/유전율연구
A16: 체중1kg당 칼로리 | B16: 7700 | C16: kcal | D16: Wishnofsky
A19: [ 3축 단계 컷오프 — 점수→1/2/3단계 ]
A20: 축 | B20: 1단계 상한 | C20: 2단계 상한 | D20: 3단계(초과) | E20: 만점
A21: 선천 | B21: 14 | C21: 28 | D21: ~40 | E21: 40
A22: 대사 | B22: 11 | C22: 24 | D22: ~35 | E22: 35
A23: 생활 | B23: 8 | C23: 17 | D23: ~25 | E23: 25

Sheet 1_설문90문항
B2: ① 설문 90문항 (흡수30·활동30·저장30)
B3: ★성격=몸(파랑)/습관(주황)/정신(초록) | 출제○=24문항 선별(축당8) | 가중=핵심1.5·일반1.0·보조0.8
B4: 📋 선택지(4단계): 전혀 아니다(0) · 아니다(1) · 그렇다(2) · 매우 그렇다(3) | 역방향=뒤집어 계산(3-점수)
B5: 【흡수력】 a1~a30
B6: ID | C6: 방향 | D6: 문항 | E6: 성격 | F6: 출제 | G6: 가중
B7: a1 | C7: 정 | D7: 식당에 가면 메뉴판을 꼼꼼히 본다 | E7: 정신 | G7: 0.8
B8: a2 | C8: 정 | D8: 음식 냄새만 맡아도 배가 고파진다 | E8: 몸 | G8: 1
B9: a3 | C9: 역 | D9: 밥상 앞에 앉으면 입맛이 없다 | E9: 몸 | F9: ○ | G9: 1.5
B10: a4 | C10: 정 | D10: 반찬도 골고루 잘 먹는다 | E10: 습관 | F10: ○ | G10: 1.5
B11: a5 | C11: 정 | D11: 밥 냄새 맡으면 저절로 주방으로 간다 | E11: 정신 | G11: 0.8
B12: a6 | C12: 역 | D12: 배탈이 자주 나는 편이다 | E12: 몸 | F12: ○ | G12: 1.5
B13: a7 | C13: 정 | D13: 새로운 음식도 호기심 있게 먹어본다 | E13: 정신 | G13: 1
B14: a8 | C14: 정 | D14: 한 번 먹을 때 양이 많은 편이다 | E14: 습관 | F14: ○ | G14: 1.5
B15: a9 | C15: 역 | D15: 편식이 심해서 먹는 게 한정적이다 | E15: 습관 | F15: ○ | G15: 1.5
B16: a10 | C16: 정 | D16: 화장실을 매일 시원하게 다녀온다 | E16: 몸 | F16: ○ | G16: 1.5
B17: a11 | C17: 정 | D17: 급식 메뉴가 대체로 다 맛있다 | E17: 정신 | G17: 0.8
B18: a12 | C18: 역 | D18: 먹어도 영양분이 흡수가 안 되는 느낌이다 | E18: 몸 | G18: 1
B19: a13 | C19: 정 | D19: 밥을 남기지 않고 다 먹는다 | E19: 습관 | G19: 1
B20: a14 | C20: 정 | D20: 음식 사진만 봐도 침이 고인다 | E20: 정신 | G20: 0.8
B21: a15 | C21: 역 | D21: 아침밥을 잘 못 먹는다 | E21: 습관 | G21: 1
B22: a16 | C22: 정 | D22: 식사 시간을 기다린다 | E22: 정신 | G22: 0.8
B23: a17 | C23: 정 | D23: 외식하면 평소보다 더 잘 먹는다 | E23: 습관 | G23: 0.8
B24: a18 | C24: 역 | D24: 영양제를 먹으면 속이 불편하다 | E24: 몸 | G24: 1
B25: a19 | C25: 정 | D25: 배고프다는 말을 자주 한다 | E25: 정신 | G25: 0.8
B26: a20 | C26: 정 | D26: 맛집 가자고 먼저 조른다 | E26: 정신 | G26: 0.8
B27: a21 | C27: 역 | D27: 입이 짧아서 조금만 먹어도 그만이다 | E27: 습관 | F27: ○ | G27: 1
B28: a22 | C28: 정 | D28: 새 반찬이 나오면 먼저 맛본다 | E28: 정신 | G28: 0.8
B29: a23 | C29: 역 | D29: 밥 먹는 속도가 또래보다 느리다 | E29: 습관 | G29: 1
B30: a24 | C30: 정 | D30: 먹는 걸 좋아한다고 자주 말한다 | E30: 정신 | G30: 0.8
B31: a25 | C31: 정 | D31: 한 그릇 뚝딱 비우고 더 달라고 한다 | E31: 습관 | F31: ○ | G31: 1
B32: a26 | C32: 역 | D32: 먹는 것에 별로 관심이 없다 | E32: 정신 | G32: 0.8
B33: a27 | C33: 정 | D33: 맛있게 먹고 소화도 잘 시킨다 | E33: 몸 | G33: 1
B34: a28 | C34: 역 | D34: 우유나 기름진 음식 먹으면 배가 아프다 | E34: 몸 | G34: 1
B35: a29 | C35: 정 | D35: 먹고 싶은 음식이 늘 분명하다 | E35: 정신 | G35: 0.8
B36: a30 | C36: 정 | D36: 간식을 입에 달고 산다 | E36: 습관 | G36: 0.8
B38: 【활동력】 b1~b30
B39: ID | C39: 방향 | D39: 문항 | E39: 성격 | F39: 출제 | G39: 가중
B40: b1 | C40: 정 | D40: 쉬는 시간이면 어느새 매점 앞에 와 있다 | E40: 습관 | G40: 0.8
B41: b2 | C41: 정 | D41: 밥 먹고 1시간도 안 돼서 또 배고프다 | E41: 몸 | F41: ○ | G41: 1.5
B42: b3 | C42: 역 | D42: 조금만 움직여도 쉽게 지친다 | E42: 몸 | F42: ○ | G42: 1.5
...

Sheet 2_인바디항목
B2: ② 인바디 + 체격 측정 — 채택 항목
B3: 실측 자료 · 주로 '몸' 판단 (저장·키) · ★=핵심 채택
B5: [1] 인바디 기본 (체성분)
B6: 항목 | C6: 채택 | D6: 반영 | E6: 점수화 | F6: 비고
B7: 체지방률(%) | C7: ★채택 | D7: 저장(몸) | E7: 낮음→저장↓ | F7: 마름/비만 핵심
B8: 골격근량(kg) | C8: ★채택 | D8: 저장(몸) | E8: 근육발달도 | F8: 마른비만 판별
B9: BMI | C9: ★채택 | D9: 저장(몸) | E9: 또래 백분위 | F9: 성장도표 비교
B10: 체중(kg) | C10: 채택 | D10: 저장(몸) | E10: 또래 대비 | F10: -
B11: 신장(cm) | C11: 채택 | D11: 키트랙 | E11: 현재키 | F11: 격차추적용
B12: FFMI(제지방지수) | C12: 채택 | D12: 저장(몸) | E12: 근육량 지표 | F12: 야구 핵심지수
B13: 내장지방 | C13: 참고 | D13: 저장(몸) | E13: 과다 경고 | F13: 보조
B14: 기초대사량 | C14: 참고 | D14: 활동(몸) | E14: 대사 추정 | F14: -
B15: 부위별근육 | C15: 미채택 | D15: - | E15: - | F15: 과함
B17: [2] ★체격 측정 (야구 선수 프레임 — 인바디 병행)
B18: 항목 | C18: 단위 | D18: 반영 | E18: 의미
B19: 윙스팬 | C19: cm | D19: 키트랙/몸 | E19: 양팔 길이. 키보다 +3~5 유리(투수)
B20: 손 크기 | C20: cm | D20: 몸 | E20: 손목~중지끝. 구종·그립력
B21: 하체 길이 | C21: cm | D21: 몸 | E21: 골반~복사뼈. 지면반발력
B22: 앉은키 비율 | C22: % | D22: 몸 | E22: 상·하체 균형
B24: [3] 인바디 → 목표 역산 (대표님 통찰)
B25: 현재(인바디) | C25: → | D25: 목표(국대) | E25: 역산 스케줄
B26: 체지방 22% | C26: → | D26: 야구 12~16% | E26: 3년: 19→17→16%
B27: 골격근 부족 | C27: → | D27: +윙스팬 프레임 | E27: 연도별 증량
B28: 악력 40kg | C28: → | D28: 65kg+ | E28: 매년 +8kg
B30: ★교차검증: 설문 저장(주관) vs 인바디(실측) 차이 크면 → 인바디 우선 → '마른비만' 경고 | 인바디 없으면 PAPS로 보조

Sheet 3_기질
B2: ③ 기질 — 생년월일·시 기반 (몸 체질 + 마음 심성 통합)
B3: ★타고난 '바탕'(기질지성). 현재(설문·인바디)가 그 위에 얹힘. 보고서엔 과학언어로 표현(사상의학 간판 최소화)
B5: [1] 타고난 몸 (체질) → 흡수·활동·저장 '바탕 ±'
B6: 체질 | C6: 한자 | D6: 타고난 경향 | E6: 흡수± | F6: 활동± | G6: 저장±
B7: 축적체 | C7: 太陰 | D7: 잘 흡수·잘 쌓음, 느긋 | E7: +1 | F7: -1 | G7: +2 | H7: 저장 바탕 강
B8: 대사체 | C8: 少陽 | D8: 빨리 태움·열많음, 활동적 | E8: 0 | F8: +2 | G8: -1 | H8: 활동 바탕 강
B9: 소화체 | C9: 少陰 | D9: 소화 여림·마른편, 예민 | E9: -2 | F9: 0 | G9: -1 | H9: 흡수 바탕 약
B10: 발달체 | C10: 太陽 | D10: 상체발달·드묾 | E10: 0 | F10: +1 | G10: -1 | H10: 희귀
B12: [2] 마음 기질 (성리 심성) → 정서·자기조절·유대감 ±
B13: 기질 | C13: 성리개념 | D13: 정서± | E13: 조절± | F13: 유대± | G13: 비고
B14: 강(剛) | C14: 굳셈·의지 | D14: +1 | E14: +1 | F14: -1 | G14: 주도형
B15: 유(柔) | C15: 순함·부드러움 | D15: +1 | E15: -1 | F15: +2 | G15: 관계형
B16: 급(急) | C16: 날램·조급 | D16: -2 | E16: -1 | F16: 0 | G16: 예민형
B17: 완(緩) | C17: 느긋·안정 | D17: +1 | E17: +1 | F17: +1 | G17: 평온형
B19: ■ 입력·반영 방법
B20: 입력: 생년월일·생시 (하나의 입력 → 몸 체질 + 마음 심성 둘 다 산출)
B21: 반영: 경향값(±) × 기질가중치 → 각 력·각 마음요소에 보정
B22: ★기질가중치 0 = 기질 OFF (스위치) | 면책: 의학·심리 진단 아님, 참고
B23: ★우리만의 표현으로 '기질'이라 부름 (사상의학·성리학 용어는 내부 근거)

Sheet 5_부모키유전
B2: ⑤ 부모키 — 유전 계산 (키 트랙, BioCode 분리)
B3: 예상키 계산 → 키 격차추적 전용 · BioCode(흡수활동저장)엔 안 들어감
B5: ■ 예상키 공식 (MPH 중간부모키)
B6: 구분 | C6: 공식 | D6: 오차범위
B7: 남아 예상키 | C7: (아빠키 + 엄마키 + 13) / 2 | D7: ± 5cm
B8: 여아 예상키 | C8: (아빠키 + 엄마키 − 13) / 2 | D8: ± 5cm
B10: ■ 키 잠재력 반영 비율
B11: 요소 | C11: 비율 | D11: 의미
B12: 부모키(유전) | C12: 0.75 | D12: 예상키의 뼈대(70~80%)
B13: 현재 성장추세 | C13: 0.20 | D13: 실제 크는 속도
B14: 환경(설문 수면·영양) | C14: 0.05 | D14: 보정
B16: ★키 트랙은 BioCode와 별개:
B17: 예상키 → 나이별 기대키(성장도표 보간) → 현재키와 격차추적
B18: 키 큰 집 마른애(부모키↑ BioCode 111) / 작은 집 통통애(부모키↓ 333) 구분

Sheet 6_목표시트
B2: ⑥ 목표 시트 — 야구 (전체 수치 수록)
B3: DB 수집 전부 · ★=재검증 · 닻=고정 · 대표님이 보고 넣고 뺄 것
B5: [1] 투수 구속 사다리
B6: 단계 | C6: 구속 | D6: 비고
B7: 리틀·중학 | C7: 120~125km | D7: ★재검증
B8: 고교 | C8: 130~140km초 | D8: 좌완130후반=프로2군선
B9: 대학 | C9: 140km | D9: KBSA
B10: KBO 우완 | C10: 143~148km | D10: 프로
B11: KBO 좌완 | C11: 138~144km | D11: 프로
B12: NPB | C12: 145km | D12: 2팀연구
B13: MLB | C13: 147km | D13: 2팀연구
B15: [2] 신장 사다리
B16: 단계 | C16: 평균 | D16: 상위 | E16: 비고
B17: 일반성인남 | C17: 173cm | D17: - | E17: 국민평균
B18: 고교야구 | C18: 176cm | D18: - | E18: 2016연구
B19: 대학 | C19: 182cm | D19: - | E19: KBSA
B20: KBO | C20: 183cm | D20: 184cm | E20: ★재검증
B21: MLB | C21: 190cm | D21: 193cm | E21: ★재검증
B23: [3] 포지션별 합격선 (프로/대학)
B24: 측정 | C24: 통과 | D24: 우수 | E24: 대학
B25: 투수 우완구속 | C25: 143km | D25: 148km+ | E25: 140km
B26: 투수 좌완구속 | C26: 138km | D26: 144km+ | E26: 135km
B27: 투수 신장 | C27: 178cm | D27: 182cm+ | E27: 178cm
B28: 야수 30m | C28: 4.1초 | D28: 3.8~3.9초 | E28: -
B29: 야수 100m | C29: - | D29: - | E29: 11.4~11.7초
B30: 야수 멀리뛰기 | C30: 250cm | D30: 275cm+ | E30: -
B31: 야수 악력 | C31: 55kg | D31: 65kg+ | E31: -
B32: 포수 팝타임 | C32: 2.0초 | D32: 1.85~1.92초 | E32: 1.95~2.05초
B34: [4] 컴바인·트레이닝장 (평균→상위10%)
B35: 항목 | C35: 평균 | D35: 상위10% | E35: 의미
B36: 30야드 대시 | C36: 3.77초 | D36: 3.50~3.60초 | E36: 주력·도루
B37: 제자리멀리뛰기 | C37: 272cm | D37: 300~312cm | E37: 수평파워
B38: 수직점프CMJ | C38: - | D38: 지면반발측정 | E38: 하체폭발
B39: 악력 | C39: - | D39: 65~70kg+ | E39: 배트·회전
B40: VO2max | C40: 일반35~40 | D40: 선수55~60+ | E40: 심폐
B41: 요요 IR2 | C41: - | D41: 20~22단계+ | E41: 프로기준
B42: 5-10-5 아질리티 | C42: - | D42: 4.10~4.30초 | E42: 방향전환
B44: [5] ★가동성·부상위험 (MLB 최중시)
B45: 항목 | C45: 측정 | D45: 기준 | E45: 의미
B46: 어깨 내외회전 | C46: 고니오미터 ° | D46: 내회전차 20도 미만 | E46: GIRD·팔꿈치부상 회피
...

Sheet 9가지경우정의
A1: 9가지 경우 정의 — 3축 × 3단계 (이것만 정의하면 27코드 자동 조합)
A2: ★ MBTI 원리: 각 자리·단계의 특성만 정의 → 조합으로 27개 생성. 같은 자리·숫자=항상 같은 특성.
A4: 【1번 선천 / 과거 / 유전 60%】
A5: 단계 | B5: 타고난몸 | C5: 체질 | D5: 정신기질 | E5: 예상키경향
A6: 1 | B6: 슬림·작은 골격 | C6: 소음인(예민 위장) | D6: 情과다·예민 | E6: 작은 편
A7: 2 | B7: 중간 프레임 | C7: 소양인(과연소) | D7: 心 주재·보통 | E7: 중간
A8: 3 | B8: 장대한 골격 | C8: 태음인(고흡수) | D8: 性 본연·강철멘탈 | E8: 큰 편
A10: 【2번 대사 / 현재 / 후천 22%】 ← "바꿀 것"이 여기
A11: 단계 | B11: 현재몸 | C11: 흡수 | D11: 식단 | E11: 식사방법 | F11: 간식
A12: 1 | B12: 마름·저장약 | C12: 막힘 | D12: 소화쉬운 고영양밀도 | E12: 6끼 분할·소량자주 | F12: 바나나·미숫가루
A13: 2 | B13: 보통 | C13: 보통 | D13: 균형식 | E13: 4~5끼 | F13: 견과·유제품
A14: 3 | B14: 잘 찜·근육잘붙음 | C14: 고흡수 | D14: 일반식+양 충분 | E14: 3끼 충분 | F14: 자유
A16: 【3번 생활 / 현재 / 후천 18%】
A17: 단계 | B17: 습관(활동) | C17: 수면 | D17: 운동방법 | E17: 수면처방
A18: 1 | B18: 정적·활동부족 | C18: 부족·불규칙 | D18: 활동량 늘리기·기초체력 | E18: 밤10시전 강제취침
A19: 2 | B19: 보통 활동 | C19: 보통 | D19: 종목훈련 유지 | E19: 규칙 유지
A20: 3 | B20: 활발·고활동 | C20: 규칙·충분 | D20: 회복·오버트레이닝 관리 | E20: 현상 유지

Sheet 27코드마스터
A1: 27 BioCode 마스터 — 9가지경우정의에서 자동 조합
A2: ★ 9가지경우정의 시트만 고치면 여기 27개가 전부 자동 갱신됩니다.
A4: 코드 | B4: 선천 | C4: 대사 | D4: 생활 | E4: 캐릭터명 | F4: 타고난몸 | G4: 체질 | H4: 정신기질 | I4: 현재몸 | J4: 흡수 | K4: 식단 | L4: 식사방법 | M4: 간식 | N4: 습관 | O4: 수면 | P4: 운동방법 | Q4: 강점 | R4: 취약점
A5: 1-1-1 | B5: 1 | C5: 1 | D5: 1 | E5: 무한성장 기대주 | F5: =9가지경우정의!B6 | G5: =9가지경우정의!C6 | H5: =9가지경우정의!D6 | I5: =9가지경우정의!B12 | J5: =9가지경우정의!C12 | K5: =9가지경우정의!D12 | L5: =9가지경우정의!E12 | M5: =9가지경우정의!F12 | N5: =9가지경우정의!B18 | O5: =9가지경우정의!C18 | P5: =9가지경우정의!D18 | Q5: =IF(AND(B5>=C5,B5>=D5),"선천",IF(AND(C5>=B5,C5>=D5),"대사","생활")) | R5: =IF(AND(B5<=C5,B5<=D5),"선천",IF(AND(C5<=B5,C5<=D5),"대사","생활"))
A6: 1-1-2 | B6: 1 | C6: 1 | D6: 2 | E6: 우리동네 골목대장 | F6: =9가지경우정의!B6 | G6: =9가지경우정의!C6 | H6: =9가지경우정의!D6 | I6: =9가지경우정의!B12 | J6: =9가지경우정의!C12 | K6: =9가지경우정의!D12 | L6: =9가지경우정의!E12 | M6: =9가지경우정의!F12 | N6: =9가지경우정의!B19 | O6: =9가지경우정의!C19 | P6: =9가지경우정의!D19 | Q6: =IF(AND(B6>=C6,B6>=D6),"선천",IF(AND(C6>=B6,C6>=D6),"대사","생활")) | R6: =IF(AND(B6<=C6,B6<=D6),"선천",IF(AND(C6<=B6,C6<=D6),"대사","생활"))
A7: 1-1-3 | B7: 1 | C7: 1 | D7: 3 | E7: 상큼발랄 팅커벨 | F7: =9가지경우정의!B6 | G7: =9가지경우정의!C6 | H7: =9가지경우정의!D6 | I7: =9가지경우정의!B12 | J7: =9가지경우정의!C12 | K7: =9가지경우정의!D12 | L7: =9가지경우정의!E12 | M7: =9가지경우정의!F12 | N7: =9가지경우정의!B20 | O7: =9가지경우정의!C20 | P7: =9가지경우정의!D20 | Q7: =IF(AND(B7>=C7,B7>=D7),"선천",IF(AND(C7>=B7,C7>=D7),"대사","생활")) | R7: =IF(AND(B7<=C7,B7<=D7),"선천",IF(AND(C7<=B7,C7<=D7),"대사","생활"))
A8: 1-2-1 | B8: 1 | C8: 2 | D8: 1 | E8: 출동준비 비행기 | F8: =9가지경우정의!B6 | G8: =9가지경우정의!C6 | H8: =9가지경우정의!D6 | I8: =9가지경우정의!B13 | J8: =9가지경우정의!C13 | K8: =9가지경우정의!D13 | L8: =9가지경우정의!E13 | M8: =9가지경우정의!F13 | N8: =9가지경우정의!B18 | O8: =9가지경우정의!C18 | P8: =9가지경우정의!D18 | Q8: =IF(AND(B8>=C8,B8>=D8),"선천",IF(AND(C8>=B8,C8>=D8),"대사","생활")) | R8: =IF(AND(B8<=C8,B8<=D8),"선천",IF(AND(C8<=B8,C8<=D8),"대사","생활"))
A9: 1-2-2 | B9: 1 | C9: 2 | D9: 2 | E9: 작은고추 매운맛 | F9: =9가지경우정의!B6 | G9: =9가지경우정의!C6 | H9: =9가지경우정의!D6 | I9: =9가지경우정의!B13 | J9: =9가지경우정의!C13 | K9: =9가지경우정의!D13 | L9: =9가지경우정의!E13 | M9: =9가지경우정의!F13 | N9: =9가지경우정의!B19 | O9: =9가지경우정의!C19 | P9: =9가지경우정의!D19 | Q9: =IF(AND(B9>=C9,B9>=D9),"선천",IF(AND(C9>=B9,C9>=D9),"대사","생활")) | R9: =IF(AND(B9<=C9,B9<=D9),"선천",IF(AND(C9<=B9,C9<=D9),"대사","생활"))
A10: 1-2-3 | B10: 1 | C10: 2 | D10: 3 | E10: 의지만렙 작은거인 | F10: =9가지경우정의!B6 | G10: =9가지경우정의!C6 | H10: =9가지경우정의!D6 | I10: =9가지경우정의!B13 | J10: =9가지경우정의!C13 | K10: =9가지경우정의!D13 | L10: =9가지경우정의!E13 | M10: =9가지경우정의!F13 | N10: =9가지경우정의!B20 | O10: =9가지경우정의!C20 | P10: =9가지경우정의!D20 | Q10: =IF(AND(B10>=C10,B10>=D10),"선천",IF(AND(C10>=B10,C10>=D10),"대사","생활")) | R10: =IF(AND(B10<=C10,B10<=D10),"선천",IF(AND(C10<=B10,C10<=D10),"대사","생활"))
A11: 1-3-1 | B11: 1 | C11: 3 | D11: 1 | E11: 엔진빵빵 클래식카 | F11: =9가지경우정의!B6 | G11: =9가지경우정의!C6 | H11: =9가지경우정의!D6 | I11: =9가지경우정의!B14 | J11: =9가지경우정의!C14 | K11: =9가지경우정의!D14 | L11: =9가지경우정의!E14 | M11: =9가지경우정의!F14 | N11: =9가지경우정의!B18 | O11: =9가지경우정의!C18 | P11: =9가지경우정의!D18 | Q11: =IF(AND(B11>=C11,B11>=D11),"선천",IF(AND(C11>=B11,C11>=D11),"대사","생활")) | R11: =IF(AND(B11<=C11,B11<=D11),"선천",IF(AND(C11<=B11,C11<=D11),"대사","생활"))
A12: 1-3-2 | B12: 1 | C12: 3 | D12: 2 | E12: 알짜배기 깡다구 | F12: =9가지경우정의!B6 | G12: =9가지경우정의!C6 | H12: =9가지경우정의!D6 | I12: =9가지경우정의!B14 | J12: =9가지경우정의!C14 | K12: =9가지경우정의!D14 | L12: =9가지경우정의!E14 | M12: =9가지경우정의!F14 | N12: =9가지경우정의!B19 | O12: =9가지경우정의!C19 | P12: =9가지경우정의!D19 | Q12: =IF(AND(B12>=C12,B12>=D12),"선천",IF(AND(C12>=B12,C12>=D12),"대사","생활")) | R12: =IF(AND(B12<=C12,B12<=D12),"선천",IF(AND(C12<=B12,C12<=D12),"대사","생활"))
A13: 1-3-3 | B13: 1 | C13: 3 | D13: 3 | E13: 대기만성 반전매력 | F13: =9가지경우정의!B6 | G13: =9가지경우정의!C6 | H13: =9가지경우정의!D6 | I13: =9가지경우정의!B14 | J13: =9가지경우정의!C14 | K13: =9가지경우정의!D14 | L13: =9가지경우정의!E14 | M13: =9가지경우정의!F14 | N13: =9가지경우정의!B20 | O13: =9가지경우정의!C20 | P13: =9가지경우정의!D20 | Q13: =IF(AND(B13>=C13,B13>=D13),"선천",IF(AND(C13>=B13,C13>=D13),"대사","생활")) | R13: =IF(AND(B13<=C13,B13<=D13),"선천",IF(AND(C13<=B13,C13<=D13),"대사","생활"))
A14: 2-1-1 | B14: 2 | C14: 1 | D14: 1 | E14: 비상임박 유망주 | F14: =9가지경우정의!B7 | G14: =9가지경우정의!C7 | H14: =9가지경우정의!D7 | I14: =9가지경우정의!B12 | J14: =9가지경우정의!C12 | K14: =9가지경우정의!D12 | L14: =9가지경우정의!E12 | M14: =9가지경우정의!F12 | N14: =9가지경우정의!B18 | O14: =9가지경우정의!C18 | P14: =9가지경우정의!D18 | Q14: =IF(AND(B14>=C14,B14>=D14),"선천",IF(AND(C14>=B14,C14>=D14),"대사","생활")) | R14: =IF(AND(B14<=C14,B14<=D14),"선천",IF(AND(C14<=B14,C14<=D14),"대사","생활"))
A15: 2-1-2 | B15: 2 | C15: 1 | D15: 2 | E15: 내일향한 숨고르기 | F15: =9가지경우정의!B7 | G15: =9가지경우정의!C7 | H15: =9가지경우정의!D7 | I15: =9가지경우정의!B12 | J15: =9가지경우정의!C12 | K15: =9가지경우정의!D12 | L15: =9가지경우정의!E12 | M15: =9가지경우정의!F12 | N15: =9가지경우정의!B19 | O15: =9가지경우정의!C19 | P15: =9가지경우정의!D19 | Q15: =IF(AND(B15>=C15,B15>=D15),"선천",IF(AND(C15>=B15,C15>=D15),"대사","생활")) | R15: =IF(AND(B15<=C15,B15<=D15),"선천",IF(AND(C15<=B15,C15<=D15),"대사","생활"))
A16: 2-1-3 | B16: 2 | C16: 1 | D16: 3 | E16: 안절부절 바른생활 | F16: =9가지경우정의!B7 | G16: =9가지경우정의!C7 | H16: =9가지경우정의!D7 | I16: =9가지경우정의!B12 | J16: =9가지경우정의!C12 | K16: =9가지경우정의!D12 | L16: =9가지경우정의!E12 | M16: =9가지경우정의!F12 | N16: =9가지경우정의!B20 | O16: =9가지경우정의!C20 | P16: =9가지경우정의!D20 | Q16: =IF(AND(B16>=C16,B16>=D16),"선천",IF(AND(C16>=B16,C16>=D16),"대사","생활")) | R16: =IF(AND(B16<=C16,B16<=D16),"선천",IF(AND(C16<=B16,C16<=D16),"대사","생활"))
A17: 2-2-1 | B17: 2 | C17: 2 | D17: 1 | E17: 여유만만 도련님 | F17: =9가지경우정의!B7 | G17: =9가지경우정의!C7 | H17: =9가지경우정의!D7 | I17: =9가지경우정의!B13 | J17: =9가지경우정의!C13 | K17: =9가지경우정의!D13 | L17: =9가지경우정의!E13 | M17: =9가지경우정의!F13 | N17: =9가지경우정의!B18 | O17: =9가지경우정의!C18 | P17: =9가지경우정의!D18 | Q17: =IF(AND(B17>=C17,B17>=D17),"선천",IF(AND(C17>=B17,C17>=D17),"대사","생활")) | R17: =IF(AND(B17<=C17,B17<=D17),"선천",IF(AND(C17<=B17,C17<=D17),"대사","생활"))
A18: 2-2-2 | B18: 2 | C18: 2 | D18: 2 | E18: 이세계의 무게중심 | F18: =9가지경우정의!B7 | G18: =9가지경우정의!C7 | H18: =9가지경우정의!D7 | I18: =9가지경우정의!B13 | J18: =9가지경우정의!C13 | K18: =9가지경우정의!D13 | L18: =9가지경우정의!E13 | M18: =9가지경우정의!F13 | N18: =9가지경우정의!B19 | O18: =9가지경우정의!C19 | P18: =9가지경우정의!D19 | Q18: =IF(AND(B18>=C18,B18>=D18),"선천",IF(AND(C18>=B18,C18>=D18),"대사","생활")) | R18: =IF(AND(B18<=C18,B18<=D18),"선천",IF(AND(C18<=B18,C18<=D18),"대사","생활"))
A19: 2-2-3 | B19: 2 | C19: 2 | D19: 3 | E19: 바른생활 부반장 | F19: =9가지경우정의!B7 | G19: =9가지경우정의!C7 | H19: =9가지경우정의!D7 | I19: =9가지경우정의!B13 | J19: =9가지경우정의!C13 | K19: =9가지경우정의!D13 | L19: =9가지경우정의!E13 | M19: =9가지경우정의!F13 | N19: =9가지경우정의!B20 | O19: =9가지경우정의!C20 | P19: =9가지경우정의!D20 | Q19: =IF(AND(B19>=C19,B19>=D19),"선천",IF(AND(C19>=B19,C19>=D19),"대사","생활")) | R19: =IF(AND(B19<=C19,B19<=D19),"선천",IF(AND(C19<=B19,C19<=D19),"대사","생활"))
A20: 2-3-1 | B20: 2 | C20: 3 | D20: 1 | E20: 폭풍흡수 먹방러 | F20: =9가지경우정의!B7 | G20: =9가지경우정의!C7 | H20: =9가지경우정의!D7 | I20: =9가지경우정의!B14 | J20: =9가지경우정의!C14 | K20: =9가지경우정의!D14 | L20: =9가지경우정의!E14 | M20: =9가지경우정의!F14 | N20: =9가지경우정의!B18 | O20: =9가지경우정의!C18 | P20: =9가지경우정의!D18 | Q20: =IF(AND(B20>=C20,B20>=D20),"선천",IF(AND(C20>=B20,C20>=D20),"대사","생활")) | R20: =IF(AND(B20<=C20,B20<=D20),"선천",IF(AND(C20<=B20,C20<=D20),"대사","생활"))
A21: 2-3-2 | B21: 2 | C21: 3 | D21: 2 | E21: 뷔페 환영 보일러 | F21: =9가지경우정의!B7 | G21: =9가지경우정의!C7 | H21: =9가지경우정의!D7 | I21: =9가지경우정의!B14 | J21: =9가지경우정의!C14 | K21: =9가지경우정의!D14 | L21: =9가지경우정의!E14 | M21: =9가지경우정의!F14 | N21: =9가지경우정의!B19 | O21: =9가지경우정의!C19 | P21: =9가지경우정의!D19 | Q21: =IF(AND(B21>=C21,B21>=D21),"선천",IF(AND(C21>=B21,C21>=D21),"대사","생활")) | R21: =IF(AND(B21<=C21,B21<=D21),"선천",IF(AND(C21<=B21,C21<=D21),"대사","생활"))
A22: 2-3-3 | B22: 2 | C22: 3 | D22: 3 | E22: 노력형 디젤엔진 | F22: =9가지경우정의!B7 | G22: =9가지경우정의!C7 | H22: =9가지경우정의!D7 | I22: =9가지경우정의!B14 | J22: =9가지경우정의!C14 | K22: =9가지경우정의!D14 | L22: =9가지경우정의!E14 | M22: =9가지경우정의!F14 | N22: =9가지경우정의!B20 | O22: =9가지경우정의!C20 | P22: =9가지경우정의!D20 | Q22: =IF(AND(B22>=C22,B22>=D22),"선천",IF(AND(C22>=B22,C22>=D22),"대사","생활")) | R22: =IF(AND(B22<=C22,B22<=D22),"선천",IF(AND(C22<=B22,C22<=D22),"대사","생활"))
A23: 3-1-1 | B23: 3 | C23: 1 | D23: 1 | E23: 파업선언 장군님 | F23: =9가지경우정의!B8 | G23: =9가지경우정의!C8 | H23: =9가지경우정의!D8 | I23: =9가지경우정의!B12 | J23: =9가지경우정의!C12 | K23: =9가지경우정의!D12 | L23: =9가지경우정의!E12 | M23: =9가지경우정의!F12 | N23: =9가지경우정의!B18 | O23: =9가지경우정의!C18 | P23: =9가지경우정의!D18 | Q23: =IF(AND(B23>=C23,B23>=D23),"선천",IF(AND(C23>=B23,C23>=D23),"대사","생활")) | R23: =IF(AND(B23<=C23,B23<=D23),"선천",IF(AND(C23<=B23,C23<=D23),"대사","생활"))
A24: 3-1-2 | B24: 3 | C24: 1 | D24: 2 | E24: 멘탈소심 거인 | F24: =9가지경우정의!B8 | G24: =9가지경우정의!C8 | H24: =9가지경우정의!D8 | I24: =9가지경우정의!B12 | J24: =9가지경우정의!C12 | K24: =9가지경우정의!D12 | L24: =9가지경우정의!E12 | M24: =9가지경우정의!F12 | N24: =9가지경우정의!B19 | O24: =9가지경우정의!C19 | P24: =9가지경우정의!D19 | Q24: =IF(AND(B24>=C24,B24>=D24),"선천",IF(AND(C24>=B24,C24>=D24),"대사","생활")) | R24: =IF(AND(B24<=C24,B24<=D24),"선천",IF(AND(C24<=B24,C24<=D24),"대사","생활"))
A25: 3-1-3 | B25: 3 | C25: 1 | D25: 3 | E25: 예민보스 모범생 | F25: =9가지경우정의!B8 | G25: =9가지경우정의!C8 | H25: =9가지경우정의!D8 | I25: =9가지경우정의!B12 | J25: =9가지경우정의!C12 | K25: =9가지경우정의!D12 | L25: =9가지경우정의!E12 | M25: =9가지경우정의!F12 | N25: =9가지경우정의!B20 | O25: =9가지경우정의!C20 | P25: =9가지경우정의!D20 | Q25: =IF(AND(B25>=C25,B25>=D25),"선천",IF(AND(C25>=B25,C25>=D25),"대사","생활")) | R25: =IF(AND(B25<=C25,B25<=D25),"선천",IF(AND(C25<=B25,C25<=D25),"대사","생활"))
A26: 3-2-1 | B26: 3 | C26: 2 | D26: 1 | E26: 이중생활 천재선수 | F26: =9가지경우정의!B8 | G26: =9가지경우정의!C8 | H26: =9가지경우정의!D8 | I26: =9가지경우정의!B13 | J26: =9가지경우정의!C13 | K26: =9가지경우정의!D13 | L26: =9가지경우정의!E13 | M26: =9가지경우정의!F13 | N26: =9가지경우정의!B18 | O26: =9가지경우정의!C18 | P26: =9가지경우정의!D18 | Q26: =IF(AND(B26>=C26,B26>=D26),"선천",IF(AND(C26>=B26,C26>=D26),"대사","생활")) | R26: =IF(AND(B26<=C26,B26<=D26),"선천",IF(AND(C26<=B26,C26<=D26),"대사","생활"))
A27: 3-2-2 | B27: 3 | C27: 2 | D27: 2 | E27: 성장계의 엄친아 | F27: =9가지경우정의!B8 | G27: =9가지경우정의!C8 | H27: =9가지경우정의!D8 | I27: =9가지경우정의!B13 | J27: =9가지경우정의!C13 | K27: =9가지경우정의!D13 | L27: =9가지경우정의!E13 | M27: =9가지경우정의!F13 | N27: =9가지경우정의!B19 | O27: =9가지경우정의!C19 | P27: =9가지경우정의!D19 | Q27: =IF(AND(B27>=C27,B27>=D27),"선천",IF(AND(C27>=B27,C27>=D27),"대사","생활")) | R27: =IF(AND(B27<=C27,B27<=D27),"선천",IF(AND(C27<=B27,C27<=D27),"대사","생활"))
A28: 3-2-3 | B28: 3 | C28: 2 | D28: 3 | E28: 직진형 에너자이저 | F28: =9가지경우정의!B8 | G28: =9가지경우정의!C8 | H28: =9가지경우정의!D8 | I28: =9가지경우정의!B13 | J28: =9가지경우정의!C13 | K28: =9가지경우정의!D13 | L28: =9가지경우정의!E13 | M28: =9가지경우정의!F13 | N28: =9가지경우정의!B20 | O28: =9가지경우정의!C20 | P28: =9가지경우정의!D20 | Q28: =IF(AND(B28>=C28,B28>=D28),"선천",IF(AND(C28>=B28,C28>=D28),"대사","생활")) | R28: =IF(AND(B28<=C28,B28<=D28),"선천",IF(AND(C28<=B28,C28<=D28),"대사","생활"))
A29: 3-3-1 | B29: 3 | C29: 3 | D29: 1 | E29: 불타오른 야생마 | F29: =9가지경우정의!B8 | G29: =9가지경우정의!C8 | H29: =9가지경우정의!D8 | I29: =9가지경우정의!B14 | J29: =9가지경우정의!C14 | K29: =9가지경우정의!D14 | L29: =9가지경우정의!E14 | M29: =9가지경우정의!F14 | N29: =9가지경우정의!B18 | O29: =9가지경우정의!C18 | P29: =9가지경우정의!D18 | Q29: =IF(AND(B29>=C29,B29>=D29),"선천",IF(AND(C29>=B29,C29>=D29),"대사","생활")) | R29: =IF(AND(B29<=C29,B29<=D29),"선천",IF(AND(C29<=B29,C29<=D29),"대사","생활"))
A30: 3-3-2 | B30: 3 | C30: 3 | D30: 2 | E30: 성장가능 가치주 | F30: =9가지경우정의!B8 | G30: =9가지경우정의!C8 | H30: =9가지경우정의!D8 | I30: =9가지경우정의!B14 | J30: =9가지경우정의!C14 | K30: =9가지경우정의!D14 | L30: =9가지경우정의!E14 | M30: =9가지경우정의!F14 | N30: =9가지경우정의!B19 | O30: =9가지경우정의!C19 | P30: =9가지경우정의!D19 | Q30: =IF(AND(B30>=C30,B30>=D30),"선천",IF(AND(C30>=B30,C30>=D30),"대사","생활")) | R30: =IF(AND(B30<=C30,B30<=D30),"선천",IF(AND(C30<=B30,C30<=D30),"대사","생활"))
A31: 3-3-3 | B31: 3 | C31: 3 | D31: 3 | E31: 성장판 프리패스상 | F31: =9가지경우정의!B8 | G31: =9가지경우정의!C8 | H31: =9가지경우정의!D8 | I31: =9가지경우정의!B14 | J31: =9가지경우정의!C14 | K31: =9가지경우정의!D14 | L31: =9가지경우정의!E14 | M31: =9가지경우정의!F14 | N31: =9가지경우정의!B20 | O31: =9가지경우정의!C20 | P31: =9가지경우정의!D20 | Q31: =IF(AND(B31>=C31,B31>=D31),"선천",IF(AND(C31>=B31,C31>=D31),"대사","생활")) | R31: =IF(AND(B31<=C31,B31<=D31),"선천",IF(AND(C31<=B31,C31<=D31),"대사","생활"))

Sheet 종목요구코드
A1: 종목별 요구 BioCode DB (초안 — KBO·MLB 실측 출처로 교체 필요)
A2: ★ 키 숫자는 임시 추정. 실제는 논문·백서의 KBO/대학/MLB 데이터로 교체. 각 숫자 출처 명시.
A4: 종목·포지션 | B4: 요구선천 | C4: 요구대사 | D4: 요구생활 | E4: 요구코드 | F4: 상위10%키(성인) | G4: 핵심요구 | H4: 출처(채울것) | I4: 체급 설계 공식 (중등 기준) | J4: 골격근량 목표 (비율) | K4: 체지방률 최적 범위 | L4: 피지컬 핵심 역량
A5: 야구 투수 | B5: 3 | C5: 2 | D5: 2 | E5: =B5&"-"&C5&"-"&D5 | F5: 185+ | G5: 큰골격·긴팔(공각도) | H5: KBO투수 프로필 ▶ | I5: 키 - 102 (파워형 체격) | J5: 목표 체중의 48% | K5: 14% ~ 16% (파워선수형) | L5: 구속 회전력, 관절 회복 완충력
A6: 야구 내야수 | B6: 2 | C6: 2 | D6: 3 | E6: =B6&"-"&C6&"-"&D6 | F6: 175~178 | G6: 적당키·순발력·민첩 | H6: KBO내야수 ▶ | I6: 키 - 106 (민첩형 체격) | J6: 목표 체중의 51% | K6: 11% ~ 13% (민첩야수형) | L6: 주력, 송구 탄력, 순발력
A7: 야구 외야수 | B7: 2 | C7: 3 | D7: 3 | E7: =B7&"-"&C7&"-"&D7 | F7: 178~183 | G7: 파워+스피드 | H7: KBO외야수 ▶ | I7: 키 - 106 (민첩형 체격) | J7: 목표 체중의 51% | K7: 11% ~ 13% (민첩야수형) | L7: 주력, 송구 탄력, 순발력
A8: 야구 포수 | B8: 3 | C8: 3 | D8: 2 | E8: =B8&"-"&C8&"-"&D8 | F8: 178~183 | G8: 다부진체격·강어깨 | H8: KBO포수 ▶ | I8: 키 - 102 (파워형 체격) | J8: 목표 체중의 48% | K8: 14% ~ 16% (파워선수형) | L8: 구속 회전력, 관절 회복 완충력
A9: 축구 필드 | B9: 1 | C9: 2 | D9: 3 | E9: =B9&"-"&C9&"-"&D9 | F9: 170~178 | G9: 지구력·하체근력 | H9: 대한축구협회 ▶ | I9: 키 - 108 (고지구력 체격) | J9: 목표 체중의 52% | K9: 10% ~ 12% (고지구력형) | L9: 스프린트 연속성, 산소 섭취 근효율
A10: 농구 | B10: 3 | C10: 2 | D10: 3 | E10: =B10&"-"&C10&"-"&D10 | F10: 185+ | G10: 최대키·점프 | H10: KBL ▶ | I10: 키 - 106 (탄력성 체격) | J10: 목표 체중의 50% | K10: 11% ~ 13% (바스켓볼형) | L10: 리바운드 체공력, 순간 가감속
A11: 수영 | B11: 2 | C11: 2 | D11: 3 | E11: =B11&"-"&C11&"-"&D11 | F11: 175~185 | G11: 긴팔다리·지구력 | H11: 수영연맹 ▶
A12: 승마 | B12: 1 | C12: 1 | D12: 2 | E12: =B12&"-"&C12&"-"&D12 | F12: 작을수록 | G12: 가볍고 작은몸 | H12: 승마협회 ▶
A13: 축구 골키퍼 | B13: 2 | C13: 1 | D13: 3 | E13: =B13&"-"&C13&"-"&D13 | F13: 183+ | G13: 공중볼 장악력, 수비 범위 몸싸움 | H13: K리그 골키퍼 프로필 ▶ | I13: 키 - 103 (대형 수비 체격) | J13: 목표 체중의 49% | K13: 12% ~ 15% (골키퍼형) | L13: 공중볼 장악력, 수비 범위 몸싸움
A14: 격투 (씨름/유도/레슬링) | B14: 3 | C14: 2 | D14: 1 | E14: =B14&"-"&C14&"-"&D14 | F14: 체급별 상이 | G14: 지면 반발력, 중심 제어력, 코어 압착력 | H14: 대한체육회 ▶ | I14: 키 - 95 (중량파워형 체격) | J14: 목표 체중의 44% | K14: 18% ~ 22% (중량파워형) | L14: 지면 반발력, 중심 제어력, 코어 압착력
A15: 회전 (체조/피겨/다이빙) | B15: 1 | C15: 3 | D15: 2 | E15: =B15&"-"&C15&"-"&D15 | F15: 경량형 | G15: 공중 회전 토크, 회전 반경 제어력, 착지 완충력 | H15: 체조협회 ▶ | I15: 키 - 115 (극초경량형 체격) | J15: 목표 체중의 54% | K15: 8% ~ 10% (극초경량형) | L15: 공중 회전 토크, 회전 반경 제어력, 착지 완충력

Sheet ★백서연결
A1: ⚠ v13: 엔진 단어 ↔ 백서 근거 1:1. 새 항목(종목요구코드·나이별경로·70/30)도 백서 근거 필요 (추가 작업).
B3: 🔗 엔진 ↔ 백서 연결표 (v11)
B4: 새 3축(선천·대사·생활)의 각 계산이 백서 어느 장 근거인지 알려줍니다. 상담 시 이 표로 근거를 댑니다.
B6: ■ A. 엔진 계산 → 백서 근거
B7: 엔진 항목 | C7: 계산/규칙 | D7: 백서 장 | E7: 설명 한 줄 (부모용)
B8: 선천축-유전키 | C8: 부모키 MPH 잠재력 | D8: 제1장 | E8: 부모키로 예상키 분산 36%·유전율 74% 설명
B9: 선천축-음양오행 | C9: 만세력 오행 스코어 | D9: 제3·8장 | E9: 생년월일시 오행 우세로 타고난 대사 경향
B10: 선천축-사상체질 | C10: 소음/소양/태음 매핑 | D10: 제3·8장 | E10: 체질별 흡수·기질차. 소음인=위장 예민·흡수 한계
B11: 선천축-심성정 | C11: 성리학 사단칠정 | D11: 제8장 | E11: 심(통제)·성(기질)·정(감정) 정서 예민성 수치화
B12: 대사축-인바디 | C12: 체성분 실측 50% | D12: 제6장 | E12: 골격근·체지방·BMI로 저장·흡수 효율
B13: 대사축-위장설문 | C13: 소화·흡수 예민성 | D13: 제2·8장 | E13: 신경성 위장→교감신경→소화효소 최대42%↓
B14: 생활축-수면설문 | C14: 수면·신체활동 70% | D14: 제5장 | E14: 깊은잠 성장호르몬 4.5배·활동량
B15: 단계 컷오프 | C15: 축별 만점 3등분 | D15: 제7장 | E15: PAPS·MLB 20-80을 3단계로
B16: 종목 목표(1.15) | C16: 선수 사다리 보정 | D16: 제7장 | E16: KBO·MLB 실측 목표. 종목 특성 슬라이딩(표시만)
B17: 27패턴 분포 | C17: 출현율 가우시안 | D17: 5.근거시234 | E17: 2-2-2가 30.5% 최다. 정규분포 역산
B19: ■ B. 근거 사슬
B20: 엔진(상담) → 백서(근거) → 각주 [리스트:태그] → 참고리스트(원문대장) → 논문 원문. 백서 각주 끝 태그를 리스트 분류에서 찾으면 원문 연결.

Sheet 5. 가중치 및 비율 근거 자료
A1: BioCode 333 가중치 및 27개 패턴 비율 설계 근거 (국내외 논문 및 학술지 기준)
A2: 구분 | B2: 설계값 및 비율 | C2: 학술지 및 논문 근거 (Scientific Evidence) | D2: 상세 메커니즘 | E2: 매칭 데이터 소스 코드
A3: 축별 가중치 (40% : 35% : 25%) | B3: Body (40%) Metabolism (35%) Behavior (25%) | C3: 대한소아청소년과학회 성장학회지 / AJHB (American Journal of Human Biology) - '소아청소년의 유전적 성장 잠재력과 후천적 환경 요인의 기여도 분석' | D3: 인간의 키 성장에서 유전 및 선천 골격이 차지하는 성향점수 비중은 약 40-45%로 수렴함. 대사 및 흡수율(30-35%), 후천 행동(20-25%)의 다중회귀모형 베타 계수값 근거. | E3: Ref-01 / MPH-Model
A4: 중앙 집중 분포 (2-2-2 패턴: 45.4%) | B4: 2-2-2 패턴 예상 분포: 45.46% | C4: 한국기계연구원/사이즈코리아 국가신체실측조사 데이터 및 다변량 정규분포(Multivariate Normal Distribution) 이론 - '대한민국 청소년기 신체 발달의 표준 가우시안 지표 및 3차원 클러스터링' | D4: Z-score ±1.0 범위 내에 인구의 약 68.2%가 밀집되는 통계학적 규칙을 3개 축에 결합. 모든 조건이 평균에 수렴하는 비율을 역산하면 45.46% 도출. | E4: Ref-02 / Stat-Gaussian
A5: 상위 1% 미만 극단치 분포 (3-3-3, 1-1-1) | B5: 3-3-3(최상): 0.73% 1-1-1(최하): 0.02% | C5: 질병관리청 소아청소년 성장도표 극단치 통계(3rd, 97th Percentile 컷오프) - '한국 아동 성장 곡선의 극단적 백분위값 분포 특성' | D5: 3개 축 모두에서 상위 10% 이내(Z > 1.28) 혹은 하위 10% 이내(Z < -1.28)에 동시에 걸칠 확률을 베이지안 조건부 확률(Joint Probability)로 계산하여 소수점 단위 통계 구현. | E5: Ref-03 / KDCA-Percentile
A6: 대사/예민성 연동 (X-1-X 패턴 감점) | B6: Metabolism 1단계 수렴 비율 역산 | C6: 대한한의학회지 / 사상체질의학회 - '소음인 기질적 예민성이 위장관 운동성 및 영양 흡수율에 미치는 임상적 영향' | D6: 신경성 위장관 장애를 겪는 아동의 경우 자율신경계 교감신경 흥분으로 소화 효소 분비가 최대 42% 감소한다는 임상 데이터 반영. Metabolism 축 점수 하락 유도. | E6: Ref-04 / KIOM-Sasang
A7: 종목별 선수 신체 특성 (야구/스포츠 가중치) | B7: 야구: KBO 투수(184cm) MLB 투수(193cm) 축구/농구: 민첩성/점프력 | C7: PHYSICAL UP 백서 제7장 및 국내 고교야구선수 등속성 근력 기준치(김수현 외, 2016; 2017) | D7: KBO/MLB 프로 레벨의 피지컬 사다리를 타깃 상수로 고정. 고교 선수의 허리 신근 및 주관절 근력 균형 데이터 기반으로 종목 가중 다이나믹 컷오프 연동. | E7: WhitePaper-Ch7 / Ref-c,d
A8: 생년월일시 연동 (사상의학/성리학 기질) | B8: 오행[木火土金水] 스코어링 소음인/소양인/태음인 자동 매핑 | C8: 한국한의학연구원(KIOM) 체질정보 뱅크 및 동의수세보원(이제마) - 성리학 사단칠정론 기반 정서 예민성 연동 모형 | D8: 생년월일시 만세력 파싱 후 [金/水] 기운 우세 시 소음인(정서 예민성, 위장관 대사 흡수 한계) 상수로 매핑. AI API 실시간 통신 없이 100% 오프라인 수식(Rule-based) 연산 보장. | E8: Ref-04 / Sasang-Rule
A9: 성리학 심리 3대 변수 (정서 및 멘탈 분석) | B9: 1. 심(心) - 컨트롤타워 2. 성(性) - 선천적 기질 3. 정(情) - 후천적 감정 | C9: 한국학중앙연구원 성리학 퇴계-율곡 사단칠정론(四端七情論) 정서 메커니즘 해석 | D9: 선천적 성향인 [성(性)], 후천적 감정 변화인 [정(情)], 이를 주재하는 정신적 컨트롤타워 [심(心)]의 3대 변수를 수치화. 아동의 훈련 강박 및 멘탈 예민성을 정교하게 추적하여 가중치 반영. | E9: NeoConfucian-Mind

Sheet 속설·습관 처방
B2: ⑧ 속설깨기 + 습관 진단 — 보고서 마무리·습관축 근거
B3: 속설=부모 오해 바로잡기(채널·보고서 떡밥) / 습관=생활습관 좋고나쁨 진단 → 습관축 반영
B5: ■ [A] 속설깨기 — '오해 → 진실 → 희망 메시지'
B6: 속설(오해) | C6: 진실 | D6: 한 줄 희망 메시지 | E6: 근거
B7: 털 나면 키 멈춘다 | C7: 털 '나기 시작'=급성장 신호, '다 굵은 후'=둔화. 순서가 핵심 | D7: 털 보여도 아직 한참 큰다! | E7: §8
B8: 발 크면 키 큰다 | C8: 말단(발·손) 먼저 큼 → 곧 다리뼈·키 급성장 (원위→근위) | D8: 발 갑자기 커졌다=키 클 타이밍! | E8: §9
B9: 팔다리 길면 키 큰다 | C9: 손발·종아리 먼저 → 대퇴골·척추 마지막. 다리 길면 성장잠재력↑ | D9: 슬림하고 다리 길면 큰키 바탕! | E9: §10
B10: 근력운동하면 키 안 큰다 | C10: ★올바른 근력운동은 성장 촉진(GH·IGF-1↑·골밀도↑). 울프의 법칙 | D10: 바른 근력운동은 키도 키운다! | E10: §12
B11: 키 크는 영양제가 마법 | C11: 대부분 건강기능식품. 결핍 아동만 catch-up 효과 | D11: 잘 먹는 아이는 영양제 불필요! | E11: §13
B12: 키 크는 기계 효과 | C12: 의학적 근거 약함. 비싼 돈 낭비 주의 | D12: 돈은 좋은 음식·수면에! | E12: §14
B13: 물 마시면 흡수 방해 | C13: 물 자체는 성장·뼈 직접 안 막음 (식사 중 과량만 주의) | D13: 적당한 물은 문제 없다! | E13: §19
B15: ■ [B] 습관 진단 — 좋은/나쁜 습관 → 습관축 반영 + 처방
B16: 습관 | C16: 좋음/나쁨·영향 | D16: 처방(나아갈 길) | E16: 근거
B17: 카페인(콜라·에너지) | C17: 나쁨: 철·칼슘 흡수방해+수면방해(GH↓) | D17: 탄산·에너지음료 끊기, 숨은 카페인 주의 | E17: §21A
B18: 스마트폰 야간 | C18: 나쁨: 움직임 뺏고 늦잠→수면·활동 저해 | D18: 취침 1시간 전 끄기, 낮 활동 늘리기 | E18: §21B
B19: 좌식 생활 | C19: 나쁨: 활동량↓ 기초대사↓ | D19: 30분마다 일어나기, 점프·스트레칭 | E19: §21
B20: 불규칙 배변 | C20: 나쁨: 장 흡수 저하 신호 | D20: 규칙적 식사·발효식품·수분 | E20: §21
B21: 야식·취침전 식사 | C21: 나쁨: 수면질↓ 성장호르몬 방해 | D21: 취침 2~3시간 전 식사 마치기 | E21: §22
B22: 충분한 수면(밤 10시전) | C22: ★좋음: 깊은수면=성장호르몬 최대 분비 | D22: 밤 10~새벽2시 숙면 사수 | E22: §3·22
B23: 점프 운동(농구·배구) | C23: ★좋음: 성장판 자극→키 성장 | D23: 주 3회 점프·줄넘기 | E23: §12
B24: 우유 1~2잔 | C24: ★좋음: 칼슘·단백질 (과량은 불필요) | D24: 하루 1~2잔, 두유 대체 가능 | E24: §18
B26: ★ 속설=보고서 마무리 '안심 멘트' / 습관=습관축 점수 + 처방 로드맵에 직접 연결 (근거 §=근거DB)

Sheet ★사용설명서
A1: ⚠ v13 갱신: 3축 비율 60:22:18 (컨트롤패널 참조) / 종목 상위10% 기준 / 9가지경우 자동조합. 아래 옛 40:35:25 설명은 참고용.
B3: BioCode 333 통합세트 v11.0
B4: 📖 엔진 사용설명서 (SOP)
B5: 이 시트만 따라 하면 누구나 BioCode를 계산하고 백서로 설명할 수 있습니다.
B7: ■ 0. 큰 그림 — 엔진은 무엇을 하나
B8: 7개 입력 → 3축(선천·대사·생활) 점수 → 단계(1·2·3) → BioCode 세 자리 → 27패턴 → 처방
B9: 핵심: 코드 첫째자리=선천(타고난 것), 둘째=대사(먹고 흡수·저장), 셋째=생활(수면·활동). 예) 1-2-2
B11: ■ 1. 입력값 7개와 3축 배분
B12: 입력값 | C12: 보는 것 | D12: 선천40 | E12: 대사35 | F12: 생활25
B13: 유전키(부모키) | C13: 신장 잠재력 | D13: 30 | E13: - | F13: -
B14: 음양오행(만세력) | C14: 생년월일시 오행 | D14: 25 | E14: - | F14: -
B15: 사상의학 체질 | C15: 체질 상수 | D15: 25 | E15: - | F15: -
B16: 심·성·정 기질 | C16: 선천 정서 | D16: 20 | E16: - | F16: -
B17: 인바디 실측 | C17: 체성분 | D17: - | E17: 50 | F17: 20
B18: 설문(정신·위장) | C18: 예민성 | D18: - | E18: 50 | F18: 10
B19: 설문(수면·활동)
B20: ★ 각 축 가중치: 선천40% · 대사35% · 생활25% (합100). 유전키는 선천 안에 포함(BioCode 반영), 목표키 산정에도 활용
B22: ■ 2. BioCode 계산 6단계 ([가중치 매트릭스] 시트에서)
B23: 단계 | C23: 이름 | D23: 하는 일
B24: STEP 1 | C24: 입력 수집 | D24: 부모키·생년월일시·인바디·설문 받기
B25: STEP 2 | C25: 선천 산출 | D25: 만세력 오행+사상체질+심성정+유전키 → 선천 점수(40점 만점)
B26: STEP 3 | C26: 대사 산출 | D26: 인바디50+위장설문50 → 대사 점수(35점 만점)
B27: STEP 4 | C27: 생활 산출 | D27: 수면설문70+위장10+인바디20 → 생활 점수(25점 만점)
B28: STEP 5 | C28: 단계 변환 | D28: [3축 등급기준] 시트로 각 축 1·2·3단계
B29: STEP 6 | C29: 코드·처방 | D29: 세 단계 이어붙여 BioCode → [27패턴]에서 캐릭터+처방
B31: ■ 3. 단계 컷오프 (축별 만점이 달라 구간도 다름)
B32: 축 | C32: 만점 | D32: 1단계(Low) | E32: 2단계(Med) | F32: 3단계(High)
B33: 선천 Body | C33: 40 | D33: 0~14 | E33: 14~28 | F33: 28~40
B34: 대사 Metabolism | C34: 35 | D34: 0~11 | E34: 11~24 | F34: 24~35
B35: 생활 Behavior | C35: 25 | D35: 0~8 | E35: 8~17 | F35: 17~25
B37: ■ 4. 15% 종목보정 — 목표에만, 기준숫자엔 미적용
B38: 1.15 계수는 [가중치 매트릭스]의 변수박스. 아이 실제 치수·BioCode·예상키는 그대로 두고, 목표 스펙(KBO·대학 사다리) 표시에만 종목 특성(농구·배구↑)을 슬라이딩 반영. 계산 숫자는 절대 안 건드림.
B40: ■ 5. 흔한 실수 체크
B41: □ 코드 자리 순서 = 선천-대사-생활 (흡수·활동·저장 아님)
B42: □ 각 축 만점 다름(40·35·25) → 컷오프도 다름
B43: □ 유전키는 선천 안에 포함(BioCode 반영). 목표키 산정에도 씀
B44: □ 15% 보정은 목표 표시에만, 점수·예상키엔 미적용
B45: □ 설문 역채점 문항 뒤집었는지 (6-점수)
B47: ▶ 계산의 근거(왜?)는 「★백서연결」 시트 + 「5.근거자료」 시트에서 확인
B49: ■ 참고: 만세력 DB는 별도 파일
...

Sheet 0_엔진전체도
B2: ⚙️ PHYSICAL UP 엔진 — 전체도
B3: 입력 → 3력(흡수·활동·저장) → 컷오프 → BioCode → 27유형 → 처방 (단위: %)
B5: ■ [표1] 5대 이력값 반영비율 — 큰 합 = 100 (★대표님 확정 예정)
B6: 이력값 | C6: 반영비율 | D6: 비고
B7: ①설문 | D7: 현재 상태 — 주축(생활·식욕·정서)
B8: ②인바디 | D8: 현재 몸 실측 — 저장·활동
B9: ③기질(생년월일) | D9: 타고난 — 사상체질+성리 심성
B10: ④유전(부모키) | D10: 키 잠재력 — 키트랙 별도
B11: 합계 | C11: =SUM(C7:C10) | D11: ★반드시 100 (대표님이 노란칸 채우면 자동합산)
B13: ■ [표2] 각 이력값 → 흡수·활동·저장 배분 — 가로 합 = 100
B14: 이력값 | C14: 흡수력 | D14: 활동력 | E14: 저장력 | F14: 가로합 | G14: 상세
B15: ①설문 | C15: 40 | D15: 35 | E15: 25 | F15: =SUM(C15:E15) | G15: 시트1
B16: ②인바디 | C16: 0 | D16: 40 | E16: 60 | F16: =SUM(C16:E16) | G16: 시트2
B17: ③기질 | C17: 40 | D17: 30 | E17: 30 | F17: =SUM(C17:E17) | G17: 시트3
B18: ④유전 | C18: 키트랙 | F18: - | G18: 시트5
B19: ★ 가로합 100 (인바디=흡수0·활동40·저장60 대표님 확정) | 흡수력 세로합은 무관
B21: ■ BioCode 자동 산출 — ★노란칸에 점수 입력하면 BioCode 자동
B22: ① 입력값별 원점수(0~100) + 큰 비중(%) ※샘플: 마른 야구소년
B23: 입력값 | C23: 흡수점수 | D23: 활동점수 | E23: 저장점수 | F23: 큰비중%
B24: 설문 | C24: 60 | D24: 80 | E24: 25 | F24: 55
B25: 인바디 | C25: 0 | D25: 50 | E25: 20 | F25: 25
B26: 기질 | C26: 55 | D26: 52 | E26: 47 | F26: 20
B27: 비중합 | C27: → 100 확인 | F27: =SUM(F24:F26)
B29: ② 최종 3력 점수 → 단계 → BioCode (표2 배분 × 위 원점수, 자동)
B30: 력 | C30: 점수 | D30: 단계 | E30: 의미
B31: 흡수력 | C31: =ROUND((C24*C15*$F$24+C25*C16*$F$25+C26*C17*$F$26)/(C15*$F$24+C16*$F$25+C17*$F$26),0) | D31: =IF(C31<=40,1,IF(C31<=65,2,3)) | E31: =IF(C31<=40,"낮음",IF(C31<=65,"보통","높음"))
B32: 활동력 | C32: =ROUND((D24*D15*$F$24+D25*D16*$F$25+D26*D17*$F$26)/(D15*$F$24+D16*$F$25+D17*$F$26),0) | D32: =IF(C32<=40,1,IF(C32<=65,2,3)) | E32: =IF(C32<=40,"낮음",IF(C32<=65,"보통","높음"))
B33: 저장력 | C33: =ROUND((E24*E15*$F$24+E25*E16*$F$25+E26*E17*$F$26)/(E15*$F$24+E16*$F$25+E17*$F$26),0) | D33: =IF(C33<=40,1,IF(C33<=65,2,3)) | E33: =IF(C33<=40,"낮음",IF(C33<=65,"보통","높음"))
B35: ➡️ BioCode | D35: =D31&D32&D33 | F35: → 시트7에서 유형명 확인
B37: ★ 노란칸(원점수·비중)이나 표2 배분%를 바꾸면 → 점수·단계·BioCode 자동 재계산
